<?xml version="1.0" encoding="UTF-8"?>
<!--
            z    y
            ^   ^
            |  /
            | /
      _______________ > x
-->
<robot name="Cat">

  <link name="chassis">
    <collision>
      <origin rpy="0 0 0" xyz="0 0 0.02"/>
      <geometry>
        <box size="0.14 0.1 0.04"/>
      </geometry>
    </collision>
     <inertial>
      <mass value="0.4"/>
      <inertia ixx="0.001" ixy="0.0" ixz="0.0" iyy="0.001" iyz="0.0" izz="0.001"/>
    </inertial>
  </link>

  <link name="fl1_link">
    <collision>
      <origin rpy="0 0 0" xyz="-0.0 -0.005 0.01"/>
      <geometry>
        <box size="0.02 0.041 0.041"/>
      </geometry>
    </collision>
    <inertial>
      <mass value="0.07"/>
      <inertia ixx="0.001" ixy="0.0" ixz="0.0" iyy="0.001" iyz="0.0" izz="0.001"/>
    </inertial>
  </link>
   
  <link name="fl2_link">
    <collision>
      <origin rpy="0 0 0" xyz="0 0 -0.03"/>
      <geometry>
        <box size="0.02 0.005 0.07"/>
      </geometry>
    </collision>
     <inertial>
      <mass value="0.07"/>
      <inertia ixx="0.001" ixy="0.0" ixz="0.0" iyy="0.001" iyz="0.0" izz="0.001"/>
    </inertial>
  </link>

  <link name="fl3_link">
   <collision>
      <origin rpy="0 0 0" xyz="0 0.0 -0.04"/>
      <geometry>
        <box size="0.01 0.005 0.07"/>
      </geometry>
    </collision>
    <inertial>
      <mass value="0.05"/>
      <inertia ixx="0.001" ixy="0.0" ixz="0.0" iyy="0.001" iyz="0.0" izz="0.001"/>
    </inertial>
  </link>

  <link name="fl4_link">
    <collision>
      <origin rpy="0 0 0" xyz="0 0.0 0.01"/>
      <geometry>
        <sphere radius="0.01"/>
      </geometry>
    </collision>
    <inertial>
      <mass value="0.01"/>
      <inertia ixx="0.001" ixy="0.0" ixz="0.0" iyy="0.001" iyz="0.0" izz="0.001"/>
    </inertial>
    <contact>
      <stiffness value="10000"/>
      <damping value="10"/>
      <lateral_friction value="1.0"/>
    </contact>
  </link>

  <link name="fr1_link">
    <collision>
      <origin rpy="0 0 0" xyz="0.0 0.01 0.01"/>
      <geometry>
        <box size="0.02 0.041 0.041"/>
      </geometry>
    </collision>
    <inertial>
      <mass value="0.07"/>
      <inertia ixx="0.001" ixy="0.0" ixz="0.0" iyy="0.001" iyz="0.0" izz="0.001"/>
    </inertial>
  </link>
   
  <link name="fr2_link">
    <collision>
      <origin rpy="0 0 0" xyz="0 0 -0.03"/>
      <geometry>
        <box size="0.02 0.005 0.07"/>
      </geometry>
    </collision>
    <inertial>
      <mass value="0.07"/>
      <inertia ixx="0.001" ixy="0.0" ixz="0.0" iyy="0.001" iyz="0.0" izz="0.001"/>
    </inertial>
  </link>

  <link name="fr3_link">
    <collision>
      <origin rpy="0 0 0" xyz="0 0.0 -0.04"/>
      <geometry>
        <box size="0.01 0.005 0.07"/>
      </geometry>
    </collision>
    <inertial>
      <mass value="0.05"/>
      <inertia ixx="0.001" ixy="0.0" ixz="0.0" iyy="0.001" iyz="0.0" izz="0.001"/>
    </inertial>
  </link>

  <link name="fr4_link">
    <collision>
      <origin rpy="0 0 0" xyz="0 0.0 0.01"/>
      <geometry>
        <sphere radius="0.01"/>
      </geometry>
    </collision>
    <inertial>
      <mass value="0.01"/>
      <inertia ixx="0.001" ixy="0.0" ixz="0.0" iyy="0.001" iyz="0.0" izz="0.001"/>
    </inertial>
    <contact>
      <stiffness value="10000"/>
      <damping value="10"/>
      <lateral_friction value="1.0"/>
    </contact>
  </link>

  <link name="bl1_link">
    <collision>
      <origin rpy="0 0 0" xyz="0.0 -0.01 0.01"/>
      <geometry>
        <box size="0.02 0.041 0.041"/>
      </geometry>
    </collision>
    <inertial>
      <mass value="0.07"/>
      <inertia ixx="0.001" ixy="0.0" ixz="0.0" iyy="0.001" iyz="0.0" izz="0.001"/>
    </inertial>
  </link>
   
  <link name="bl2_link">
    <collision>
      <origin rpy="0 0 0" xyz="0 0 -0.03"/>
      <geometry>
        <box size="0.02 0.005 0.07"/>
      </geometry>
    </collision>
     <inertial>
      <mass value="0.07"/>
      <inertia ixx="0.001" ixy="0.0" ixz="0.0" iyy="0.001" iyz="0.0" izz="0.001"/>
    </inertial>
  </link>

  <link name="bl3_link">
    <collision>
      <origin rpy="0 0 0" xyz="0 0.0 -0.04"/>
      <geometry>
        <box size="0.01 0.005 0.07"/>
      </geometry>
    </collision>
    <inertial>
      <mass value="0.05"/>
      <inertia ixx="0.001" ixy="0.0" ixz="0.0" iyy="0.001" iyz="0.0" izz="0.001"/>
    </inertial>
  </link>

  <link name="bl4_link">
    <collision>
      <origin rpy="0 0 0" xyz="0 0.0 0.01"/>
      <geometry>
        <sphere radius="0.01"/>
      </geometry>
    </collision>
    <inertial>
      <mass value="0.01"/>
      <inertia ixx="0.001" ixy="0.0" ixz="0.0" iyy="0.001" iyz="0.0" izz="0.001"/>
    </inertial>
    <contact>
      <stiffness value="10000"/>
      <damping value="10"/>
      <lateral_friction value="1.0"/>
    </contact>
  </link>

  <link name="br1_link">
    <collision>
      <origin rpy="0 0 0" xyz="0.0 0.01 0.01"/>
      <geometry>
        <box size="0.02 0.041 0.041"/>
      </geometry>
    </collision>
    <inertial>
      <mass value="0.07"/>
      <inertia ixx="0.001" ixy="0.0" ixz="0.0" iyy="0.001" iyz="0.0" izz="0.001"/>
    </inertial>
  </link>
   
  <link name="br2_link">
    <collision>
      <origin rpy="0 0 0" xyz="0 0 -0.03"/>
      <geometry>
        <box size="0.02 0.005 0.07"/>
      </geometry>
    </collision>
     <inertial>
      <mass value="0.07"/>
      <inertia ixx="0.001" ixy="0.0" ixz="0.0" iyy="0.001" iyz="0.0" izz="0.001"/>
    </inertial>
  </link>

  <link name="br3_link">
    <collision>
      <origin rpy="0 0 0" xyz="0 0.0 -0.04"/>
      <geometry>
        <box size="0.01 0.005 0.07"/>
      </geometry>
    </collision>
    <inertial>
      <mass value="0.05"/>
      <inertia ixx="0.001" ixy="0.0" ixz="0.0" iyy="0.001" iyz="0.0" izz="0.001"/>
    </inertial>
  </link>
  
  <link name="br4_link">
    <collision>
      <origin rpy="0 0 0" xyz="0 0.0 0.01"/>
      <geometry>
        <sphere radius="0.01"/>
      </geometry>
    </collision>
    <inertial>
      <mass value="0.01"/>
      <inertia ixx="0.001" ixy="0.0" ixz="0.0" iyy="0.001" iyz="0.0" izz="0.001"/>
    </inertial>
    <contact>
      <stiffness value="10000"/>
      <damping value="10"/>
      <lateral_friction value="1.0"/>
    </contact>
  </link>

  <link name="mz_link">
      <collision>
          <origin rpy="0 0 0" xyz="0 0.0 0.0"/>
          <geometry>
              <box size="0.05 0.05 0.01"/>
          </geometry>
      </collision>
      <inertial>
          <mass value="0.0001"/>
          <inertia ixx="0.001" ixy="0.0" ixz="0.0" iyy="0.001" iyz="0.0" izz="0.001"/>
      </inertial>
      <contact>
          <stiffness value="10000"/>
          <damping value="10"/>
          <lateral_friction value="1.0"/>
      </contact>
  </link>
  <link name="my_link">
      <collision>
          <origin rpy="0 0 0" xyz="0 0.0 0.0"/>
          <geometry>
              <box size="0.02 0.02 0.05"/>
          </geometry>
      </collision>
      <inertial>
          <mass value="0.0001"/>
          <inertia ixx="0.001" ixy="0.0" ixz="0.0" iyy="0.001" iyz="0.0" izz="0.001"/>
      </inertial>
      <contact>
          <stiffness value="10000"/>
          <damping value="10"/>
          <lateral_friction value="1.0"/>
      </contact>
  </link>

  <!-- front left -->
 <joint name="fl1" type="revolute">
    <parent link="chassis"/>
    <child link="fl1_link"/>

    <origin xyz="0.097 0.045 0" rpy="0 0 0" />
    <axis xyz="1 0 0" />
    <limit effort="100" velocity="100" lower="-0.698132" upper="0.698132" />
  </joint>

  <joint name="fl2" type="revolute">
    <parent link="fl1_link"/>
    <child link="fl2_link"/>

    <origin xyz="0 0.035 -0.025" rpy="0 0 0" />
    <axis xyz="0 1 0" />
    <limit effort="100" velocity="100" lower="-1.57079632679" upper="1.57079632679" />
  </joint>

  <joint name="fl3" type="revolute">
    <parent link="fl2_link"/>
    <child link="fl3_link"/>

    <origin xyz="0 0.0 -0.07" rpy="0 0 0" />
    <axis xyz="0 1 0" />
    <limit effort="100" velocity="100" lower="-3.14159265359" upper="0.0" />
  </joint>

  <joint name="fl4" type="fixed">
    <parent link="fl3_link"/>
    <child link="fl4_link"/>
    
    <origin xyz="0 0 -0.08" rpy="0 0 0" />
    <axis xyz="0 1 0" />
    <limit effort="100" velocity="100" lower="-3.14159265359" upper="3.14159265359" />
  </joint>

  <!-- front right -->
  <joint name="fr1" type="revolute">
    <parent link="chassis"/>
    <child link="fr1_link"/>

    <origin xyz="0.097 -0.045 0" rpy="0 0 0" />
    <axis xyz="1 0 0" />
    <limit effort="100" velocity="100" lower="-0.698132" upper="0.698132" />
  </joint>

  <joint name="fr2" type="revolute">
    <parent link="fr1_link"/>
    <child link="fr2_link"/>

    <origin xyz="0 -0.035 -0.025" rpy="0 0 0" />
    <axis xyz="0 1 0" />
    <limit effort="100" velocity="100" lower="-1.57079632679" upper="1.57079632679" />
  </joint>

  <joint name="fr3" type="revolute">
    <parent link="fr2_link"/>
    <child link="fr3_link"/>

    <origin xyz="0 0.0 -0.07" rpy="0 0 0" />
    <axis xyz="0 1 0" />
    <limit effort="100" velocity="100" lower="-3.14159265359" upper="0.0" />
  </joint>

  <joint name="fr4" type="fixed">
    <parent link="fr3_link"/>
    <child link="fr4_link"/>
    
    <origin xyz="0 0 -0.08" rpy="0 0 0" />
    <axis xyz="0 1 0" />
    <limit effort="100" velocity="100" lower="-3.14159265359" upper="3.14159265359" />
  </joint>

<!-- back left -->
 <joint name="bl1" type="revolute">
    <parent link="chassis"/>
    <child link="bl1_link"/>

    <origin xyz="-0.097 0.045 0" rpy="0 0 0" />
    <axis xyz="1 0 0" />
    <limit effort="100" velocity="100" lower="-0.698132" upper="0.698132" />
  </joint>

  <joint name="bl2" type="revolute">
    <parent link="bl1_link"/>
    <child link="bl2_link"/>

    <origin xyz="0 0.035 -0.025" rpy="0 0 0" />
    <axis xyz="0 1 0" />
    <limit effort="100" velocity="100" lower="-1.57079632679" upper="1.57079632679" />
  </joint>

  <joint name="bl3" type="revolute">
    <parent link="bl2_link"/>
    <child link="bl3_link"/>

    <origin xyz="0 0.0 -0.07" rpy="0 0 0" />
    <axis xyz="0 1 0" />
    <limit effort="100" velocity="100" lower="-3.14159265359" upper="0.0" />
  </joint>

  <joint name="bl4" type="fixed">
    <parent link="bl3_link"/>
    <child link="bl4_link"/>
    
    <origin xyz="0 0 -0.08" rpy="0 0 0" />
    <axis xyz="0 1 0" />
    <limit effort="100" velocity="100" lower="-3.14159265359" upper="3.14159265359" />
  </joint>

<!-- back right -->
  <joint name="br1" type="revolute">
    <parent link="chassis"/>
    <child link="br1_link"/>

    <origin xyz="-0.097 -0.045 0" rpy="0 0 0" />
    <axis xyz="1 0 0" />
    <limit effort="100" velocity="100" lower="-0.698132" upper="0.698132" />
  </joint>

  <joint name="br2" type="revolute">
    <parent link="br1_link"/>
    <child link="br2_link"/>

    <origin xyz="0 -0.035 -0.025" rpy="0 0 0" />
    <axis xyz="0 1 0" />
    <limit effort="100" velocity="100" lower="-1.57079632679" upper="1.57079632679" />
  </joint>

  <joint name="br3" type="revolute">
    <parent link="br2_link"/>
    <child link="br3_link"/>

    <origin xyz="0 0.0 -0.07" rpy="0 0 0" />
    <axis xyz="0 1 0" />
    <limit effort="100" velocity="100" lower="-3.14159265359" upper="0.0" />
  </joint>
  
  <joint name="br4" type="fixed">
    <parent link="br3_link"/>
    <child link="br4_link"/>
    
    <origin xyz="0 0 -0.08" rpy="0 0 0" />
    <axis xyz="0 1 0" />
    <limit effort="100" velocity="100" lower="-3.14159265359" upper="3.14159265359" />
  </joint>

  <joint name="mz" type="revolute">
      <parent link="chassis"/>
      <child link="mz_link"/>
      
      <origin xyz="0.15 0 0" rpy="0 0 0" />
      <axis xyz="0 0 1" />
      <limit effort="100" velocity="100" lower="-1.57079632679" upper="1.57079632679" />
  </joint>

  <joint name="my" type="revolute">
      <parent link="mz_link"/>
      <child link="my_link"/>
      
      <origin xyz="0.03 0 0.03" rpy="0 0 0" />
      <axis xyz="0 1 0" />
      <limit effort="100" velocity="100" lower="-1.57079632679" upper="1.57079632679" />
  </joint>

</robot>
